Workbook

Sheet demand_display
A1: Demand age bin | B1: Under 25 | D1: 25-34 | F1: 35-54 | H1: 65-74 | J1: 75+ | M1: Total
A2: Radius | B2: 2m | C2: 5m | D2: 2m | E2: 5m | F2: 2m | G2: 5m | H2: 2m | I2: 5m | J2: 2m | K2: 5m | M2: 2m | N2: 5m
A3: Total households | B3: 67709 | C3: 325704 | D3: 250041 | E3: 1284003 | F3: 908074 | G3: 4745762 | H3: 218374 | I3: 1287558 | J3: 177018 | K3: 1166849 | M3: =SUMIF(B$2:K$2, "2m", B3:K3) -> 1621216 | N3: =SUMIF(B$2:K$2, "5m", B3:K3) -> 8809876
A4: % Renters | B4: 0.9 | C4: 0.9 | D4: 0.56 | E4: 0.56 | F4: 0.313 | G4: 0.313 | H4: 0.21 | I4: 0.21 | J4: 0.23 | K4: 0.23 | M4: =AVERAGEIF(B$2:K$2, "2m", B4:K4) -> 0.4426 | N4: =AVERAGEIF(B$2:K$2, "5m", B4:K4) -> 0.4426
A5: Total Renters | B5: 60938 | C5: 293134 | D5: 140023 | E5: 719042 | F5: 284530 | G5: 1487005 | H5: 45859 | I5: 270387 | J5: 40714 | K5: 268375 | M5: =SUMIF(B$2:K$2, "2m", B5:K5) -> 572064 | N5: =SUMIF(B$2:K$2, "5m", B5:K5) -> 3037943
A6: Rental Demand (40% turnover assumption) | B6: 24375 | C6: 117254 | D6: 56009 | E6: 287617 | F6: 113812 | G6: 594802 | H6: 18344 | I6: 108155 | J6: 16286 | K6: 107350 | M6: =SUMIF(B$2:K$2, "2m", B6:K6) -> 228826 | N6: =SUMIF(B$2:K$2, "5m", B6:K6) -> 1215178
A7: Addressable Demand (2% capture) | B7: 488 | C7: 2345 | D7: 1120 | E7: 5752 | F7: 2276 | G7: 11896 | H7: 367 | I7: 2163 | J7: 326 | K7: 2147 | M7: =SUMIF(B$2:K$2, "2m", B7:K7) -> 4577 | N7: =SUMIF(B$2:K$2, "5m", B7:K7) -> 24303
A11: Total | B11: =M1 -> Total
A12: =A2 -> Radius | B12: =M2 -> 2m | C12: =N2 -> 5m
A13: =A3 -> Total households | B13: =M3 -> 1621216 | C13: =N3 -> 8809876
A14: =A4 -> % Renters | B14: =M4 -> 0.4426 | C14: =N4 -> 0.4426
A15: =A5 -> Total Renters | B15: =M5 -> 572064 | C15: =N5 -> 3037943
A16: =A6 -> Rental Demand (40% turnover assumption) | B16: =M6 -> 228826 | C16: =N6 -> 1215178
A19: Class A Units
A20: Studio
A21: 1BR | B21: =supply!B19 -> 318
A22: 2BR | B22: =supply!B20 -> 312
A23: 3BR | B23: =supply!B21 -> 54
A24: 4BR | B24: =supply!B22 -> 0
A25: Class B Units
A26: 1BR | B26: =supply!C19 -> 1188
A27: 2BR | B27: =supply!C20 -> 2364
A28: 3BR | B28: =supply!C21 -> 861
A29: 4BR | B29: =supply!C22 -> 151
A30: Class C Units
A31: 1BR | B31: =supply!D19 -> 1475
A32: 2BR | B32: =supply!D20 -> 3508
A33: 3BR | B33: =supply!D21 -> 1024
A34: 4BR | B34: =supply!D22 -> 25
A36: Total | B36: =SUM(B21:B34) -> 11280
A39: =A7 -> Addressable Demand (2% capture) | B39: =M7 -> 4577 | C39: =N7 -> 24303

Sheet supply
A1: Radius | B1: 2 Mile Radius | C1: 2 Mile Radius | D1: 2 Mile Radius | E1: 5 Mile Radius | F1: 5 Mile Radius | G1: 5 Mile Radius
A2: Building Class | B2: A | C2: B | D2: C | E2: A | F2: B | G2: C
A3: Metric
A4: % 1-Bed | B4: 0.501 | C4: 0.3908 | D4: 0.3581 | E4: 0.5103 | F4: 0.4693 | G4: 0.4623
A5: % 2-Bed | B5: 0.4365 | C5: 0.5195 | D5: 0.6872 | E5: 0.4127 | F5: 0.5214 | G5: 0.6971
A6: % 3-Bed | B6: 0.125 | C6: 0.3055 | D6: 0.2514 | E6: 0.1251 | F6: 0.285 | G6: 0.3744
A7: % 4-Bed | C7: 0.0999 | D7: 0.0679 | E7: 1 | F7: 0.2388 | G7: 0.6461
A8: % Studios | C8: 0.3241 | D8: 0.1415 | E8: 0.099 | F8: 0.2884 | G8: 0.3627
A9: Avg Asking/SF | B9: 2 | C9: 1 | D9: 1 | E9: 2 | F9: 2 | G9: 1
A10: Avg Asking/Unit | B10: 2090 | C10: 1252 | D10: 1164 | E10: 1873 | F10: 1498 | G10: 1281
A11: Avg Unit SF | B11: 982 | C11: 1031 | D11: 976 | E11: 947 | F11: 1074 | G11: 950
A12: Four Bedroom Asking Rent/SF | C12: 1 | D12: 1 | F12: 1 | G12: 1
A13: Four Bedroom Asking Rent/Unit | C13: 1724 | D13: 2079 | F13: 2267 | G13: 2264
A14: Four Bedroom Avg SF | C14: 1644 | D14: 1925 | F14: 1828 | G14: 1765
A15: Four Bedroom Effective Rent/SF | C15: 1 | D15: 1 | F15: 1 | G15: 1
A16: Four Bedroom Effective Rent/Unit | C16: 1652 | D16: 2058 | F16: 2210 | G16: 2245
A17: Four Bedroom Vacancy % | C17: 0.1595 | D17: 0.12 | F17: 0.0997 | G17: 0.065
A18: Four Bedroom Vacant Units | B18: 0 | C18: 58 | D18: 3 | E18: 0 | F18: 66 | G18: 6
A19: Number Of 1 Bedroom Units | B19: 318 | C19: 1188 | D19: 1475 | E19: 5277 | F19: 8920 | G19: 5728
A20: Number Of 2 Bedroom Units | B20: 312 | C20: 2364 | D20: 3508 | E20: 4271 | F20: 11057 | G20: 10270
A21: Number Of 3 Bedroom Units | B21: 54 | C21: 861 | D21: 1024 | E21: 645 | F21: 2710 | G21: 2606
A22: Number Of 4 Bedroom Units | B22: 0 | C22: 151 | D22: 25 | E22: 0 | F22: 262 | G22: 110
A23: Number Of Parking Spaces | B23: 400 | C23: 6876 | D23: 11059 | E23: 9592 | F23: 36917 | G23: 27759
A24: One Bedroom Asking Rent/SF | B24: 2 | C24: 1 | D24: 1 | E24: 2 | F24: 2 | G24: 2
A25: One Bedroom Asking Rent/Unit | B25: 1831 | C25: 1083 | D25: 1020 | E25: 1633 | F25: 1281 | G25: 1106
A26: One Bedroom Avg SF | B26: 816 | C26: 776 | D26: 734 | E26: 782 | F26: 782 | G26: 729
A27: One Bedroom Effective Rent/SF | B27: 2 | C27: 1 | D27: 1 | E27: 2 | F27: 2 | G27: 2
A28: One Bedroom Effective Rent/Unit | B28: 1809 | C28: 1064 | D28: 1004 | E28: 1592 | F28: 1254 | G28: 1090
A29: One Bedroom Vacancy % | B29: 0.0312 | C29: 0.1146 | D29: 0.1304 | E29: 0.0863 | F29: 0.1101 | G29: 0.1097
A30: Studio Asking Rent/SF | C30: 2 | D30: 1 | E30: 3 | F30: 2 | G30: 2
A31: Studio Asking Rent/Unit | C31: 911 | D31: 762 | E31: 1533 | F31: 1280 | G31: 921
A32: Studio Avg SF | C32: 583 | D32: 537 | E32: 586 | F32: 565 | G32: 502
A33: Studio Effective Rent/SF | C33: 2 | D33: 1 | E33: 3 | F33: 2 | G33: 2
A34: Studio Effective Rent/Unit | C34: 904 | D34: 757 | E34: 1485 | F34: 1253 | G34: 911
A35: Studio Vacancy % | C35: 0.0206 | D35: 0.121 | E35: 0.0725 | F35: 0.0467 | G35: 0.0933
A36: Three Bedroom Asking Rent/SF | B36: 1 | C36: 1 | D36: 1 | E36: 2 | F36: 1 | G36: 1
A37: Three Bedroom Asking Rent/Unit | B37: 1697 | C37: 1549 | D37: 1440 | E37: 2684 | F37: 1923 | G37: 1625
A38: Three Bedroom Avg SF | B38: 1415 | C38: 1363 | D38: 1316 | E38: 1424 | F38: 1445 | G38: 1318
A39: Three Bedroom Effective Rent/SF | B39: 1 | C39: 1 | D39: 1 | E39: 2 | F39: 1 | G39: 1
A40: Three Bedroom Effective Rent/Unit | B40: 1640 | C40: 1523 | D40: 1418 | E40: 2595 | F40: 1882 | G40: 1601
...
